Workbook

Sheet Maestro de Insumos 
A1: Codigo | B1: Descripción | C1: Tipo | D1: U.M. | E1: Grupo | F1: Vr.Unitario | G1: % IVA | H1: Vr.Neto | I1: Estado | J1: Sub-Analisis | K1: Stock Minimo | L1: Stock Maximo | M1: Devolutivo | N1: Adjuntos | O1: Iva Descontable | P1: Excluye IVA | Q1: Usuario Creación | R1: Fecha Creación | S1: Usuario Modificación | T1: Fecha Modificación
A2: 1 | B2: DURANTA | C2: M - INVENTARIO | D2: UND - UNIDAD | E2: 034 - OTRAS COMPRAS CTA | F2: 2000 | G2: 19 | H2: 2380 | I2: Activo | J2: NO | K2: 0 | L2: 0 | M2: NO | N2: NO | O2: SI | P2: NO | Q2: Cesar Augusto Rolon Cañon | R2: 15/11/2023
A3: 2 | B3: PALMA COLA DE ZORRO | C3: M - INVENTARIO | D3: UND - UNIDAD | E3: 034 - OTRAS COMPRAS CTA | F3: 500000 | G3: 19 | H3: 595000 | I3: Activo | J3: NO | K3: 0 | L3: 0 | M3: NO | N3: NO | O3: SI | P3: NO | Q3: Cesar Augusto Rolon Cañon | R3: 15/11/2023
A4: 3 | B4: HELICONIAS | C4: M - INVENTARIO | D4: UND - UNIDAD | E4: 034 - OTRAS COMPRAS CTA | F4: 5500 | G4: 19 | H4: 6545 | I4: Activo | J4: NO | K4: 0 | L4: 0 | M4: NO | N4: NO | O4: SI | P4: NO | Q4: Cesar Augusto Rolon Cañon | R4: 15/11/2023
A5: 4 | B5: GRAMA | C5: M - INVENTARIO | D5: M2 - METRO CUADRADO | E5: 034 - OTRAS COMPRAS CTA | F5: 9000 | G5: 19 | H5: 10710 | I5: Activo | J5: NO | K5: 0 | L5: 0 | M5: NO | N5: NO | O5: SI | P5: NO | Q5: Cesar Augusto Rolon Cañon | R5: 15/11/2023
A6: 5 | B6: CINTA ITALIANA | C6: M - INVENTARIO | D6: UND - UNIDAD | E6: 034 - OTRAS COMPRAS CTA | F6: 3500 | G6: 19 | H6: 4165 | I6: Activo | J6: NO | K6: 0 | L6: 0 | M6: NO | N6: NO | O6: SI | P6: NO | Q6: Cesar Augusto Rolon Cañon | R6: 15/11/2023
A7: 6 | B7: DIANELAS 0CCO | C7: M - INVENTARIO | D7: UND - UNIDAD | E7: 034 - OTRAS COMPRAS CTA | F7: 4000 | G7: 19 | H7: 4760 | I7: Activo | J7: NO | K7: 0 | L7: 0 | M7: NO | N7: NO | O7: SI | P7: NO | Q7: Cesar Augusto Rolon Cañon | R7: 15/11/2023
A8: 7 | B8: MANO DE OBRA 0CCO | C8: S - SERVICIOS | D8: UND - UNIDAD | E8: 037 - OTROS SERVICIOS CTA | F8: 1000000 | G8: 19 | H8: 1190000 | I8: Activo | J8: NO | K8: 0 | L8: 0 | M8: NO | N8: NO | O8: SI | P8: NO | Q8: Cesar Augusto Rolon Cañon | R8: 15/11/2023
A9: 8 | B9: DESAGUE PUSH AUTOMATICO SIN DESBORDE EN BRONCE | C9: M - INVENTARIO | D9: UND - UNIDAD | E9: 034 - OTRAS COMPRAS CTA | F9: 67143 | G9: 19 | H9: 79900 | I9: Activo | J9: NO | K9: 0 | L9: 0 | M9: NO | N9: NO | O9: SI | P9: NO | Q9: Cesar Augusto Rolon Cañon | R9: 15/11/2023
A10: 9 | B10: ACOPLE METALICO PARA MESNOCONTROL 50CM 1/2" | C10: M - INVENTARIO | D10: UND - UNIDAD | E10: 034 - OTRAS COMPRAS CTA | F10: 18403 | G10: 19 | H10: 21900 | I10: Activo | J10: NO | K10: 0 | L10: 0 | M10: NO | N10: NO | O10: SI | P10: NO | Q10: Cesar Augusto Rolon Cañon | R10: 15/11/2023
A11: 10 | B11: TAPON ROSCADO DE 1/2" | C11: M - INVENTARIO | D11: UND - UNIDAD | E11: 034 - OTRAS COMPRAS CTA | F11: 336 | G11: 19 | H11: 400 | I11: Activo | J11: NO | K11: 0 | L11: 0 | M11: NO | N11: NO | O11: SI | P11: NO | Q11: Cesar Augusto Rolon Cañon | R11: 15/11/2023
A12: 11 | B12: TAPON LISO DE 1/2" | C12: M - INVENTARIO | D12: UND - UNIDAD | E12: 034 - OTRAS COMPRAS CTA | F12: 252 | G12: 19 | H12: 300 | I12: Activo | J12: NO | K12: 0 | L12: 0 | M12: NO | N12: NO | O12: SI | P12: NO | Q12: Cesar Augusto Rolon Cañon | R12: 15/11/2023
A13: 12 | B13: TAPON ROSCADO DE 3/4" | C13: M - INVENTARIO | D13: UND - UNIDAD | E13: 034 - OTRAS COMPRAS CTA | F13: 798 | G13: 19 | H13: 950 | I13: Activo | J13: NO | K13: 0 | L13: 0 | M13: NO | N13: NO | O13: SI | P13: NO | Q13: Cesar Augusto Rolon Cañon | R13: 15/11/2023
... A17: 16 | B17: TUBO PVC DE PRESION 1" X 6MTS | C17: M - INVENTARIO | D17: UND - UNIDAD | E17: 034 - OTRAS COMPRAS CTA | F17: 26807 | G17: 19 | H17: 31900 | I17: Activo | J17: NO | K17: 0 | L17: 0 | M17: NO | N17: NO | O17: SI | P17: NO | Q17: Cesar Augusto Rolon Cañon | R17: 15/11/2023
A18: 17 | B18: CINTA TEFLON 3/4" X 15MTS | C18: M - INVENTARIO | D18: UND - UNIDAD | E18: 034 - OTRAS COMPRAS CTA | F18: 2200 | G18: 19 | H18: 2618 | I18: Activo | J18: NO | K18: 0 | L18: 0 | M18: NO | N18: NO | O18: SI | P18: NO | Q18: Cesar Augusto Rolon Cañon | R18: 15/11/2023 | S18: Direccion Administrativa | T18: 10/01/2024
A19: 18 | B19: REMOVEDOR LIMPIADOR PVC X 1/4 DE GALON | C19: M - INVENTARIO | D19: UND - UNIDAD | E19: 034 - OTRAS COMPRAS CTA | F19: 41933 | G19: 19 | H19: 49900 | I19: Activo | J19: NO | K19: 0 | L19: 0 | M19: NO | N19: NO | O19: SI | P19: NO | Q19: Cesar Augusto Rolon Cañon | R19: 15/11/2023 | S19: Ruben Dario Villabona Sarmiento | T19: 26/01/2024
A20: 19 | B20: SOLDADURA LIQUIDA PVC X 1/4 DE GALON MARCA CELTA | C20: M - INVENTARIO | D20: UND - UNIDAD | E20: 034 - OTRAS COMPRAS CTA | F20: 89500 | G20: 19 | H20: 106505 | I20: Activo | J20: NO | K20: 0 | L20: 0 | M20: NO | N20: NO | O20: SI | P20: NO | Q20: Cesar Augusto Rolon Cañon | R20: 15/11/2023 | S20: Ruben Dario Villabona Sarmiento | T20: 04/03/2024
A21: 20 | B21: ORINAL ARRECIFE REF 06106A001 | C21: M - INVENTARIO | D21: UND - UNIDAD | E21: 034 - OTRAS COMPRAS CTA | F21: 428571 | G21: 19 | H21: 510000 | I21: Activo | J21: NO | K21: 0 | L21: 0 | M21: NO | N21: NO | O21: SI | P21: NO | Q21: Cesar Augusto Rolon Cañon | R21: 15/11/2023
A22: 21 | B22: SANITARIO SMART ALONGADO COLOR BLANCO REF, O39181001 | C22: M - INVENTARIO | D22: UND - UNIDAD | E22: 034 - OTRAS COMPRAS CTA | F22: 411681 | G22: 19 | H22: 489900 | I22: Activo | J22: NO | K22: 0 | L22: 0 | M22: NO | N22: NO | O22: SI | P22: NO | Q22: Cesar Augusto Rolon Cañon | R22: 15/11/2023
A23: 22 | B23: SANITARIO ADRIÁTICO REF, O13181001 | C23: M - INVENTARIO | D23: UND - UNIDAD | E23: 034 - OTRAS COMPRAS CTA | F23: 604958 | G23: 19 | H23: 719900 | I23: Activo | J23: NO | K23: 0 | L23: 0 | M23: NO | N23: NO | O23: SI | P23: NO | Q23: Cesar Augusto Rolon Cañon | R23: 15/11/2023
A24: 23 | B24: SANITARIO POWER ONE REF, 010141001 | C24: M - INVENTARIO | D24: UND - UNIDAD | E24: 034 - OTRAS COMPRAS CTA | F24: 552941 | G24: 19 | H24: 658000 | I24: Activo | J24: NO | K24: 0 | L24: 0 | M24: NO | N24: NO | O24: SI | P24: NO | Q24: Cesar Augusto Rolon Cañon | R24: 15/11/2023
A25: 24 | B25: LAVAMANOS MARCA SENCO REFERENCIA FORTUNDA TIPO VESSEL COLOR BLANCO | C25: M - INVENTARIO | D25: UND - UNIDAD | E25: 034 - OTRAS COMPRAS CTA | F25: 142773 | G25: 19 | H25: 169900 | I25: Activo | J25: NO | K25: 0 | L25: 0 | M25: NO | N25: NO | O25: SI | P25: NO | Q25: Cesar Augusto Rolon Cañon | R25: 15/11/2023
A26: 25 | B26: GRIFERÍA MESNOCONTROL FÉNIX ALTA MARCA DECORCERAMICA CÓDIGO DG25CR001 | C26: M - INVENTARIO | D26: UND - UNIDAD | E26: 034 - OTRAS COMPRAS CTA | F26: 226891 | G26: 19 | H26: 270000 | I26: Activo | J26: NO | K26: 0 | L26: 0 | M26: NO | N26: NO | O26: SI | P26: NO | Q26: Cesar Augusto Rolon Cañon | R26: 15/11/2023
A27: 26 | B27: PANEL LED SOBREPONER CIRCULAR 1350 LÚMENES 18W LUZ FRÍA | C27: M - INVENTARIO | D27: UND - UNIDAD | E27: 034 - OTRAS COMPRAS CTA | F27: 31008 | G27: 19 | H27: 36900 | I27: Activo | J27: NO | K27: 0 | L27: 0 | M27: NO | N27: NO | O27: SI | P27: NO | Q27: Cesar Augusto Rolon Cañon | R27: 15/11/2023
A28: 27 | B28: PANEL LED 60X60 | C28: M - INVENTARIO | D28: UND - UNIDAD | E28: 034 - OTRAS COMPRAS CTA | F28: 100756 | G28: 19 | H28: 119900 | I28: Activo | J28: NO | K28: 0 | L28: 0 | M28: NO | N28: NO | O28: SI | P28: NO | Q28: Cesar Augusto Rolon Cañon | R28: 15/11/2023
A29: 28 | B29: SENSOR DE MESVIMIENTO PARA TECHO 360° | C29: M - INVENTARIO | D29: UND - UNIDAD | E29: 034 - OTRAS COMPRAS CTA | F29: 55546 | G29: 19 | H29: 66100 | I29: Activo | J29: NO | K29: 0 | L29: 0 | M29: NO | N29: NO | O29: SI | P29: NO | Q29: Cesar Augusto Rolon Cañon | R29: 15/11/2023
A30: 29 | B30: TOMA WETGUARD SEGURO INDUSTRIAL 15A - 277V L7-15P 2P 3W AMARILLO IP67 LEVITON REF. 25W34 | C30: M - INVENTARIO | D30: UND - UNIDAD | E30: 034 - OTRAS COMPRAS CTA | F30: 92654.52 | G30: 19 | H30: 110258.88 | I30: Activo | J30: NO | K30: 0 | L30: 0 | M30: NO | N30: NO | O30: SI | P30: NO | Q30: Cesar Augusto Rolon Cañon | R30: 15/11/2023 | S30: Ruben Dario Villabona Sarmiento | T30: 19/06/2024
A31: 30 | B31: CLAVIJA WETGUARD SEGURO INDUSTRIAL 15A - 277V L7-15P 2P 3W AMARILLO IP67 LEVITON REF. 24W34 | C31: M - INVENTARIO | D31: UND - UNIDAD | E31: 034 - OTRAS COMPRAS CTA | F31: 72136.15 | G31: 19 | H31: 85842.019 | I31: Activo | J31: NO | K31: 0 | L31: 0 | M31: NO | N31: NO | O31: SI | P31: NO | Q31: Cesar Augusto Rolon Cañon | R31: 15/11/2023 | S31: Ruben Dario Villabona Sarmiento | T31: 19/06/2024
A32: 31 | B32: TOMA DOBLE BLANCA CFGI | C32: M - INVENTARIO | D32: UND - UNIDAD | E32: 034 - OTRAS COMPRAS CTA | F32: 45126 | G32: 19 | H32: 53700 | I32: Activo | J32: NO | K32: 0 | L32: 0 | M32: NO | N32: NO | O32: SI | P32: NO | Q32: Cesar Augusto Rolon Cañon | R32: 15/11/2023
A33: 32 | B33: ARREGLO ESCRITORIO EN L DE 1,500CC0 | C33: S - SERVICIOS | D33: UND - UNIDAD | E33: 037 - OTROS SERVICIOS CTA | F33: 180000 | G33: 19 | H33: 214200 | I33: Activo | J33: NO | K33: 0 | L33: 0 | M33: NO | N33: NO | O33: SI | P33: NO | Q33: Cesar Augusto Rolon Cañon | R33: 15/11/2023 | S33: Ruben Dario Villabona Sarmiento | T33: 19/06/2024
A34: 33 | B34: ARREGLO ESCRITORIO DE 1,200CC0 | C34: S - SERVICIOS | D34: UND - UNIDAD | E34: 037 - OTROS SERVICIOS CTA | F34: 150000 | G34: 19 | H34: 178500 | I34: Activo | J34: NO | K34: 0 | L34: 0 | M34: NO | N34: NO | O34: SI | P34: NO | Q34: Cesar Augusto Rolon Cañon | R34: 15/11/2023
A35: 34 | B35: ARREGLO DE SILLAS ERGONOMICA0CC0 | C35: S - SERVICIOS | D35: UND - UNIDAD | E35: 037 - OTROS SERVICIOS CTA | F35: 100000 | G35: 19 | H35: 119000 | I35: Activo | J35: NO | K35: 0 | L35: 0 | M35: NO | N35: NO | O35: SI | P35: NO | Q35: Cesar Augusto Rolon Cañon | R35: 15/11/2023
A36: 35 | B36: ARREGLO DE SILLAS ASISTENCIAL0CC0 | C36: S - SERVICIOS | D36: UND - UNIDAD | E36: 037 - OTROS SERVICIOS CTA | F36: 60000 | G36: 19 | H36: 71400 | I36: Activo | J36: NO | K36: 0 | L36: 0 | M36: NO | N36: NO | O36: SI | P36: NO | Q36: Cesar Augusto Rolon Cañon | R36: 15/11/2023 | S36: Ruben Dario Villabona Sarmiento | T36: 19/06/2024
A37: 36 | B37: ARREGLO DE BIBLIOTECA 0CC0 | C37: S - SERVICIOS | D37: UND - UNIDAD | E37: 037 - OTROS SERVICIOS CTA | F37: 100000 | G37: 19 | H37: 119000 | I37: Activo | J37: NO | K37: 0 | L37: 0 | M37: NO | N37: NO | O37: SI | P37: NO | Q37: Cesar Augusto Rolon Cañon | R37: 15/11/2023
A38: 37 | B38: CILINDRO AJUSTABLE PARA SILLA ERGONOMICA | C38: M - INVENTARIO | D38: UND - UNIDAD | E38: 034 - OTRAS COMPRAS CTA | F38: 60000 | G38: 19 | H38: 71400 | I38: Activo | J38: NO | K38: 0 | L38: 0 | M38: NO | N38: NO | O38: SI | P38: NO | Q38: Cesar Augusto Rolon Cañon | R38: 15/11/2023
A39: 38 | B39: BASE ARAÑA PARA SILLA ERGONOMICA | C39: M - INVENTARIO | D39: UND - UNIDAD | E39: 034 - OTRAS COMPRAS CTA | F39: 65000 | G39: 19 | H39: 77350 | I39: Activo | J39: NO | K39: 0 | L39: 0 | M39: NO | N39: NO | O39: SI | P39: NO | Q39: Cesar Augusto Rolon Cañon | R39: 15/11/2023
A40: 39 | B40: RUEDA PARA SILLA DE OFICINA | C40: M - INVENTARIO | D40: UND - UNIDAD | E40: 034 - OTRAS COMPRAS CTA | F40: 5800 | G40: 19 | H40: 6902 | I40: Activo | J40: NO | K40: 0 | L40: 0 | M40: NO | N40: NO | O40: SI | P40: NO | Q40: Cesar Augusto Rolon Cañon | R40: 15/11/2023
A41: 40 | B41: SOPORTE PICOLORO PARA VIDRIO | C41: M - INVENTARIO | D41: UND - UNIDAD | E41: 034 - OTRAS COMPRAS CTA | F41: 62000 | G41: 19 | H41: 73780 | I41: Activo | J41: NO | K41: 0 | L41: 0 | M41: NO | N41: NO | O41: SI | P41: NO | Q41: Cesar Augusto Rolon Cañon | R41: 15/11/2023
A42: 41 | B42: VIDRIO SEPARADOR DE PUESTOS DE TRABAJO | C42: M - INVENTARIO | D42: UND - UNIDAD | E42: 034 - OTRAS COMPRAS CTA | F42: 135000 | G42: 19 | H42: 160650 | I42: Activo | J42: NO | K42: 0 | L42: 0 | M42: NO | N42: NO | O42: SI | P42: NO | Q42: Cesar Augusto Rolon Cañon | R42: 15/11/2023
A43: 42 | B43: MANTENIMIENTO LOCATIVO CC0 | C43: S - SERVICIOS | D43: UND - UNIDAD | E43: 037 - OTROS SERVICIOS CTA | F43: 0 | G43: 19 | H43: 0 | I43: Activo | J43: NO | K43: 0 | L43: 0 | M43: NO | N43: NO | O43: SI | P43: NO | Q43: Cesar Augusto Rolon Cañon | R43: 15/11/2023
...

Sheet Capítulos
A1: CAPÍTULO | B1: TIPO DE COSTO | C1: DESCRIPCIÓN
A2: ADMINISTRACION | B2: OPEX | C2: Gastos generales de oficina, papelería, servicios públicos, viáticos administrativos.
A3: RECURSOS HUMANOS | B3: OPEX | C3: Nómina, prestaciones sociales, contrataciones, bienestar laboral.
A4: SST | B4: OPEX | C4: Dotación de EPP, capacitaciones en seguridad, exámenes médicos, programas de prevención.
A5: MANTENIMIENTO RUTINARIO | B5: OPEX | C5: Actividades recurrentes como limpieza de cunetas, bacheo menor, corte de césped, señalización.
A6: MANTENIMIENTO MAYOR | B6: CAPEX | C6: Rehabilitaciones de pavimento: intervenciones programadas, no recurrentes que buscan restaurar, rehabilitar o prolongar la vida útil de la infraestructura vial
A7: OPERACION DE VIAS | B7: OPEX | C7: Personal de peajes, sistemas ITS, energía en estaciones, insumos de operación vial.
A8: POLICIA DE CARRETERAS | B8: OPEX | C8: Convenios con la Policía de Carreteras.
A9: INVERSIÓN ACTIVOS | B9: CAPEX | C9: Compra de vehículos, maquinaria, equipos de cómputo, mobiliario o infraestructura nueva.
A10: GESTION AMBIENTAL | B10: OPEX | C10: Monitoreos ambientales, cumplimiento de licencias, planes de manejo ambiental.
A11: GESTION PREDIAL | B11: OPEX | C11: Gastos de la gestión predial que no pasen por la Subcuenta
A12: GESTION SOCIAL | B12: OPEX | C12: Programas de gestión social
... A17: IMPUESTOS | B17: OPEX | C17: Impuestos prediales, ICA, retenciones, industria y comercio, impuestos de vehículos.
A22: SUCURSAL | B22: SUCURSAL ADMINISTRATIVA
A23: Presupuesto 2026 PA | B23: Patrimonio Autónomo
A24: Presupuesto 2026 CTS | B24: Concesion transversal del Sisga
A25: Presupuesto RRHH 2026 | B25: Concesion transversal del Sisga
A26: Obras de Emergencia | B26: OBRAS Menores a Cargo de la ANI

Sheet Presupuesto 2026
B2: Variable
B3: IPC (dic/dic) | C3: 4,0%
B4: Salario mínimo | C4: 0.08
B5: TRM promedio (COP/USD) | C5: $4.250
A7: Capítulo | B7: ítem | C7: Insumo | D7: Descripción | E7: Unidad | F7: Cantidad 2026 | G7: Precio Base 2025 | H7: Precio Base 2026 | I7: Valor Total | J7: Supuestos | K7: Observaciones | L7: Soporte | M7: Total Presupuesto 2026 | N7: Enero | O7: febrero | P7: marzo | Q7: abril | R7: mayo | S7: junio | T7: julio | U7: agosto | V7: septiembre | W7: octubre | X7: noviembre | Y7: diciembre
A8: =Capítulos!$A$2 -> ADMINISTRACION | B8: GASTOS GENERALES OFICINA BOGOTÁ | C8: ARRENDAMIENTO OFICINA | D8: Arrendamiento oficina Teleport 502 | E8: Mes | F8: 12 | G8: 11305000 | H8: =G8*(1+$C$3) -> 11757200 | I8: =+F8*H8 -> 141086400 | J8: Consumo estimado para el año 2026 | K8: precio según contrato | L8: Contrato de Arrendamiento suscrito en 2025 | M8: =SUM(N8:Y8) -> 141086400 | N8: =+I8/$F8 -> 11757200 | O8: =+$I$8/$F$8 -> 11757200 | P8: =+$I$8/$F$8 -> 11757200 | Q8: =+$I$8/$F$8 -> 11757200 | R8: =+$I$8/$F$8 -> 11757200 | S8: =+$I$8/$F$8 -> 11757200 | T8: =+$I$8/$F$8 -> 11757200 | U8: =+$I$8/$F$8 -> 11757200 | V8: =+$I$8/$F$8 -> 11757200 | ... Y8: =+$I$8/$F$8 -> 11757200
A9: =Capítulos!$A$2 -> ADMINISTRACION | B9: GASTOS GENERALES OFICINA BOGOTÁ | C9: ADMINISTRACIÓN OFICINA | D9: Administración oficina Teleport 502 | E9: Mes | F9: 12 | G9: 2258812 | H9: =G9*(1+$C$3) -> 2349164.5 | I9: =+F9*H9 -> 28189974 | J9: Consumo estimado para el año 2026 | K9: precio según contrato | L9: Contrato de Administración suscrito en 2025 | M9: =SUM(N9:Y9) -> 28189974 | N9: =+$I$9/$F$9 -> 2349164.5 | O9: =+$I$9/$F$9 -> 2349164.5 | P9: =+$I$9/$F$9 -> 2349164.5 | Q9: =+$I$9/$F$9 -> 2349164.5 | R9: =+$I$9/$F$9 -> 2349164.5 | S9: =+$I$9/$F$9 -> 2349164.5 | T9: =+$I$9/$F$9 -> 2349164.5 | U9: =+$I$9/$F$9 -> 2349164.5 | ... Y9: =+$I$9/$F$9 -> 2349164.5
A10: =Capítulos!$A$2 -> ADMINISTRACION | B10: GASTOS PAPELERIA OFICINA BOGOTÁ | C10: ALMOHADILLA DACTILAR | D10: Almohadilla X 4000 Huellas | E10: unidad | F10: 10 | G10: 5000 | H10: =G10*(1+$C$3) -> 5200 | I10: =+F10*H10 -> 52000 | J10: Consumo estimado para el año 2026 | K10: Precio promedio de mercado | L10: Cotización | M10: =SUM(N10:Y10) -> 52000 | O10: =+$I$10/3 -> 17333.333 | S10: =+$I$10/3 -> 17333.333 | W10: =+$I$10/3 -> 17333.333
A11: =Capítulos!$A$2 -> ADMINISTRACION | B11: GASTOS PAPELERIA OFICINA BOGOTÁ | C11: AZ CARTA AZUL PLASTIFICADO | D11: AZ para archivo | E11: unidad | F11: 500 | G11: 700 | H11: =G11*(1+$C$3) -> 728 | I11: =+F11*H11 -> 364000 | J11: Consumo estimado para el año 2026 | K11: Precio promedio de mercado | L11: Cotización | M11: =SUM(N11:Y11) -> 364000 | O11: =+$I$11/3 -> 121333.33 | S11: =+$I$11/3 -> 121333.33 | W11: =+$I$11/3 -> 121333.33
A12: =Capítulos!$A$2 -> ADMINISTRACION | B12: GASTOS PAPELERIA OFICINA BOGOTÁ | C12: AZ OFICIO AZUL PLASTIFICADO | D12: AZ para archivo | E12: unidad | F12: 1000 | G12: 800 | H12: =G12*(1+$C$3) -> 832 | I12: =+F12*H12 -> 832000 | J12: Consumo estimado para el año 2026 | K12: Precio promedio de mercado | L12: Cotización | M12: =SUM(N12:Y12) -> 832000 | O12: =+$I$12/3 -> 277333.33 | S12: =+$I$12/3 -> 277333.33 | W12: =+$I$12/3 -> 277333.33
A13: =Capítulos!$A$2 -> ADMINISTRACION | B13: GASTOS PAPELERIA OFICINA BOGOTÁ | C13: BANDERITAS COLORES | D13: Banderitas por 5 unidades paquete | E13: unidad | F13: 10 | G13: 4000 | H13: =G13*(1+$C$3) -> 4160 | I13: =+F13*H13 -> 41600 | J13: Consumo estimado para el año 2026 para las 5 sedes | K13: Precio promedio de mercado | L13: Cotización | M13: =SUM(N13:Y13) -> 41600 | O13: =+$I$13/3 -> 13866.667 | S13: =+$I$13/3 -> 13866.667 | W13: =+$I$13/3 -> 13866.667
A14: =Capítulos!$A$2 -> ADMINISTRACION | B14: GASTOS PAPELERIA OFICINA BOGOTÁ | C14: BISTURI GRANDE PLASTICO | H14: =G14*(1+$C$3) -> 0 | I14: =+F14*H14 -> 0 | M14: =SUM(N14:Y14) -> 0
A15: =Capítulos!$A$2 -> ADMINISTRACION | B15: GASTOS PAPELERIA OFICINA BOGOTÁ | C15: BLOCK AMARILLO MEDIA CARTA CUADRICULADO 50H | H15: =G15*(1+$C$3) -> 0 | I15: =+F15*H15 -> 0 | M15: =SUM(N15:Y15) -> 0
A16: =Capítulos!$A$2 -> ADMINISTRACION | B16: GASTOS PAPELERIA OFICINA BOGOTÁ | C16: BLOCK IRIS CARTA X 35 HOJAS | H16: =G16*(1+$C$3) -> 0 | I16: =+F16*H16 -> 0 | M16: =SUM(N16:Y16) -> 0
A17: =Capítulos!$A$2 -> ADMINISTRACION | B17: GASTOS PAPELERIA OFICINA BOGOTÁ | C17: BLOCK MILIMETRADO OFICIO 25H | H17: =G17*(1+$C$3) -> 0 | I17: =+F17*H17 -> 0 | M17: =SUM(N17:Y17) -> 0
A18: =Capítulos!$A$2 -> ADMINISTRACION | B18: GASTOS PAPELERIA OFICINA BOGOTÁ | C18: BOLSA DE VINILO CARTA DELGADA PAQUETE X 20 UND | H18: =G18*(1+$C$3) -> 0 | I18: =+F18*H18 -> 0 | M18: =SUM(N18:Y18) -> 0
A19: =Capítulos!$A$2 -> ADMINISTRACION | B19: GASTOS GENERALES OFICINA CCO | H19: =G19*(1+$C$3) -> 0 | I19: =+F19*H19 -> 0
A20: =Capítulos!$A$2 -> ADMINISTRACION | B20: GASTOS GENERALES AREA SERVICIOS SLG | H20: =G20*(1+$C$3) -> 0 | I20: =+F20*H20 -> 0
A21: =Capítulos!$A$2 -> ADMINISTRACION | B21: GASTOS GENERALES AREA SERVICIOS MACHETA | H21: =G21*(1+$C$3) -> 0 | I21: =+F21*H21 -> 0
A22: =Capítulos!$A$2 -> ADMINISTRACION | B22: GASTOS GENERALES PEAJE SLG | H22: =G22*(1+$C$3) -> 0 | I22: =+F22*H22 -> 0
A23: =Capítulos!$A$2 -> ADMINISTRACION | B23: GASTOS GENERALES PEAJE MACHETA | H23: =G23*(1+$C$3) -> 0 | I23: =+F23*H23 -> 0
A24: =Capítulos!$A$2 -> ADMINISTRACION | B24: BAÑOS MOVILES | H24: =G24*(1+$C$3) -> 0 | I24: =+F24*H24 -> 0
A25: =Capítulos!$A$2 -> ADMINISTRACION | B25: ASESORIAS Y AFILIACIONES | H25: =G25*(1+$C$3) -> 0 | I25: =+F25*H25 -> 0
A26: =Capítulos!A4 -> SST | B26: DOTACION | C26: CAMISAS MUJER BLANCA TALLA XS | H26: =G26*(1+$C$3) -> 0 | I26: =+F26*H26 -> 0
A27: SST | B27: DOTACION | C27: CAMISAS MUJER BLANCA TALLA S | H27: =G27*(1+$C$3) -> 0 | I27: =+F27*H27 -> 0
A28: SST | B28: DOTACION | C28: CAMISAS HOMBRE BLANCAS TALLA L | H28: =G28*(1+$C$3) -> 0 | I28: =+F28*H28 -> 0
A29: SST | B29: DOTACION | C29: CAMISAS HOMBRE BLANCAS TALLA XL | H29: =G29*(1+$C$3) -> 0 | I29: =+F29*H29 -> 0
A30: SST | B30: DOTACION | C30: CAMISAS HOMBRE AZUL TALLA L 0 CONSERJE | H30: =G30*(1+$C$3) -> 0 | I30: =+F30*H30 -> 0
A31: SST | B31: DOTACION | C31: CAMISAS HOMBRE AZUL TALLA XL 0 CONSERJE | H31: =G31*(1+$C$3) -> 0 | I31: =+F31*H31 -> 0
A32: SST | B32: DOTACION | C32: PANTALÓN JEANS MUJER TALLA 10 | H32: =G32*(1+$C$3) -> 0 | I32: =+F32*H32 -> 0
A33: SST | B33: DOTACION | C33: PANTALÓN JEANS MUJER TALLA 12 | H33: =G33*(1+$C$3) -> 0 | I33: =+F33*H33 -> 0
A34: SST | B34: DOTACION | C34: PANTALÓN JEANS HOMBRE TALLA 40 | H34: =G34*(1+$C$3) -> 0 | I34: =+F34*H34 -> 0
A35: SST | B35: DOTACION | C35: PANTALÓN JEANS HOMBRE TALLA 42 | H35: =G35*(1+$C$3) -> 0 | I35: =+F35*H35 -> 0
A36: SST | B36: DOTACION | C36: CHAQUETA TALLA XL DAMA | H36: =G36*(1+$C$3) -> 0 | I36: =+F36*H36 -> 0
A37: SST | B37: DOTACION | C37: CHAQUETA TALLA XXL HOMBRE | H37: =G37*(1+$C$3) -> 0 | I37: =+F37*H37 -> 0
A38: SST | B38: DOTACION | C38: CONJUNTO ANTIFLUIDO TALLA S | H38: =G38*(1+$C$3) -> 0 | I38: =+F38*H38 -> 0
... A48: MANTENIMIENTO RUTINARIO | B48: PINTURA | C48: PINTURA TERTRAFICO ACRILICO BASE SOLVENTE BLANCO | H48: =G48*(1+$C$3) -> 0 | I48: =+F48*H48 -> 0
A49: MANTENIMIENTO RUTINARIO | B49: PINTURA | C49: MICROESFERA DE VIDRIO TIPO I SWARCO BULTO X 25KG | E49: Bulto | F49: 20 | G49: 1000000 | H49: =G49*(1+$C$3) -> 1040000 | I49: =+H49*F49 -> 20800000 | J49: Demarcación del PR XXX al PR XXX TODAS LAS UF | K49: Precio promedio de mercado, sujeto a ajuste.
A50: MANTENIMIENTO RUTINARIO | B50: TACHAS | C50: TACHA BIDIRECCIONAL CON ESPIGO BLANCA / ROJA | H50: =G50*(1+$C$3) -> 0
A51: MANTENIMIENTO RUTINARIO | B51: TACHAS | C51: TACHA BIDIRECCIONAL CON ESPIGO AMARILLA | H51: =G51*(1+$C$3) -> 0
...

Sheet Mto Rutinario
B2: Variable
B3: IPC (dic/dic) | C3: 4,0%
B4: Salario mínimo | C4: 0.08
B5: TRM promedio (COP/USD) | C5: $4.250
A7: Capítulo | B7: ítem | C7: Insumo | D7: Descripción | E7: Unidad | F7: Cantidad 2026 | G7: Precio Base 2025 | H7: Precio Base 2026 | I7: Valor Total | J7: Supuestos | K7: Observaciones | L7: Soporte | M7: Total Presupuesto 2026 | N7: Enero | O7: febrero | P7: marzo | Q7: abril | R7: mayo | S7: junio | T7: julio | U7: agosto | V7: septiembre | W7: octubre | X7: noviembre | Y7: diciembre
A8: MANTENIMIENTO RUTINARIO | B8: PINTURA | C8: PINTURA TERTRAFICO ACRILICO BASE SOLVENTE AMARILLO | H8: =G8*(1+$C$3) -> 0 | I8: =+F8*H8 -> 0
A9: MANTENIMIENTO RUTINARIO | B9: PINTURA | C9: PINTURA TERTRAFICO ACRILICO BASE SOLVENTE BLANCO | H9: =G9*(1+$C$3) -> 0 | I9: =+F9*H9 -> 0
A10: MANTENIMIENTO RUTINARIO | B10: PINTURA | C10: MICROESFERA DE VIDRIO TIPO I SWARCO BULTO X 25KG | E10: Bulto | F10: 20 | G10: 1000000 | H10: =G10*(1+$C$3) -> 1040000 | I10: =+H10*F10 -> 20800000 | J10: Demarcación del PR XXX al PR XXX TODAS LAS UF | K10: Precio promedio de mercado, sujeto a ajuste.
A11: MANTENIMIENTO RUTINARIO | B11: TACHAS | C11: TACHA BIDIRECCIONAL CON ESPIGO BLANCA / ROJA | H11: =G11*(1+$C$3) -> 0
A12: MANTENIMIENTO RUTINARIO | B12: TACHAS | C12: TACHA BIDIRECCIONAL CON ESPIGO AMARILLA | H12: =G12*(1+$C$3) -> 0
A13: MANTENIMIENTO RUTINARIO | B13: TACHAS | C13: TACHAS EN ALUMINIO SOLAR CON ESPIGO COLOR ROJO/ROJO | H13: =G13*(1+$C$3) -> 0
A14: MANTENIMIENTO RUTINARIO | B14: AVISOS & DEFENSAS | H14: =G14*(1+$C$3) -> 0
A15: MANTENIMIENTO RUTINARIO | B15: CUNETAS Y MUROS | H15: =G15*(1+$C$3) -> 0
A16: MANTENIMIENTO RUTINARIO | B16: LIMPIEZA DA ALCANTARILLAS Y BOXCOULVERT | H16: =G16*(1+$C$3) -> 0
A17: MANTENIMIENTO RUTINARIO | B17: MANTENIMIENTO DE TALUDES | H17: =G17*(1+$C$3) -> 0
A18: MANTENIMIENTO RUTINARIO | B18: MANTENIMIENTO DE PUENTES | H18: =G18*(1+$C$3) -> 0
A19: MANTENIMIENTO RUTINARIO | B19: ROCERIA | H19: =G19*(1+$C$3) -> 0
A20: MANTENIMIENTO RUTINARIO | B20: BACHEO | C20: MEZCLA DENSA MDC0190 | D20: Mezcla densa en caliente | E20: m³ | F20: 619 | G20: 635536.78 | H20: =G20*(1+$C$3) -> 660958.25 | I20: 3.9339727e+08 | J20: Consumo estimado en pavimentación UF2, frente PR40+200. | K20: Precio según última compra 2025.
A21: MANTENIMIENTO RUTINARIO | B21: BACHEO | C21: SERVICIO INSTALACIÓN DE MEZCLA DENSA EN CALIENTE | D21: Servicio | E21: m³ | F21: 619 | G21: 800000 | H21: =G21*(1+$C$3) -> 832000 | I21: 3.9339727e+08

Sheet Mto Periódico
B2: Variable
B3: IPC (dic/dic) | C3: 4,0%
B4: Salario mínimo | C4: 0.08
B5: TRM promedio (COP/USD) | C5: $4.250
A7: Capítulo | B7: ítem | C7: Insumo | D7: Descripción | E7: Unidad | F7: Cantidad 2026 | G7: Precio Base 2025 | H7: Precio Base 2026 | I7: Valor Total | J7: Supuestos | K7: Observaciones | L7: Soporte | M7: Total Presupuesto 2026 | N7: Enero | O7: febrero | P7: marzo | Q7: abril | R7: mayo | S7: junio | T7: julio | U7: agosto | V7: septiembre | W7: octubre | X7: noviembre | Y7: diciembre
A8: MANTENIMIENTO MAYOR

Sheet Operación Vías
B2: Variable
B3: IPC (dic/dic) | C3: 0.051
B4: Salario mínimo | C4: 0.23
B5: TRM promedio (COP/USD) | C5: $4.250
A7: Capítulo | B7: ítem | C7: Insumo | D7: Descripción | E7: Unidad | F7: Cantidad 2026 | G7: Precio Base 2025 | H7: Precio Base 2026 | I7: Valor Total | J7: Supuestos | K7: Observaciones | L7: Soporte | M7: Total Presupuesto 2026 | N7: Enero | O7: febrero | P7: marzo | Q7: abril | R7: mayo | S7: junio | T7: julio | U7: agosto | V7: septiembre | W7: octubre | X7: noviembre | Y7: diciembre
A8: OPERACION DE VIAS | B8: OPERACION PEAJES | C8: OPERACION INTEGRAL ESTACIÓN DE PEAJE MACHETA | M8: =SUM(N8:Y8) -> 2.1969934e+09 | N8: =SUM(N9:N21) -> 1.9851884e+08 | O8: =SUM(O9:O21) -> 1.7971732e+08 | P8: =SUM(P9:P21) -> 1.7925955e+08 | Q8: =SUM(Q9:Q21) -> 1.7925955e+08 | R8: =SUM(R9:R21) -> 1.8097049e+08 | S8: =SUM(S9:S21) -> 1.7925955e+08 | T8: =SUM(T9:T21) -> 1.8195536e+08 | U8: =SUM(U9:U21) -> 1.8092584e+08 | ... Y8: =SUM(Y9:Y21) -> 1.8503092e+08
A9: OPERACION DE VIAS | B9: OPERACION PEAJES | C9: OPERACION INTEGRAL ESTACIÓN DE PEAJE MACHETA | D9: SERVICIO OPERACIÓN PEAJE | E9: MENSUAL | F9: 12 | G9: 126398293 | H9: =G9*(1+C$4) -> 1.554699e+08 | I9: =H9*F9 -> 1.8656388e+09 | M9: =SUM(N9:Y9) -> 1.8656388e+09 | N9: =H9 -> 1.554699e+08 | O9: =+N9 -> 1.554699e+08 | P9: =+O9 -> 1.554699e+08 | Q9: =+P9 -> 1.554699e+08 | R9: =+Q9 -> 1.554699e+08 | S9: =+R9 -> 1.554699e+08 | T9: =+S9 -> 1.554699e+08 | U9: =+T9 -> 1.554699e+08 | V9: =+U9 -> 1.554699e+08 | ... Y9: =+X9 -> 1.554699e+08
A10: OPERACION DE VIAS | B10: OPERACION PEAJES | C10: OPERACION INTEGRAL ESTACIÓN DE PEAJE MACHETA | D10: SERVICIO RECAUDADORES APOYO | E10: MENSUAL | F10: 3 | G10: =14076524/3 -> 4692174.7 | H10: =G10*(1+C$4) -> 5771374.8 | I10: =H10*F10 -> 17314125 | M10: =SUM(N10:Y10) -> 17314125 | N10: 0 | O10: 0 | P10: 0 | Q10: 0 | R10: 0 | S10: 0 | T10: 0 | U10: 0 | V10: 0 | W10: =H10 -> 5771374.8 | X10: =W10 -> 5771374.8 | Y10: =X10 -> 5771374.8
A11: OPERACION DE VIAS | B11: OPERACION PEAJES | C11: OPERACION INTEGRAL ESTACIÓN DE PEAJE MACHETA | D11: SERVICIO ALQUILER DATAFONOS | E11: MENSUAL | F11: 12 | G11: =69000*2 -> 138000 | H11: =G11*(1+C$3) -> 145038 | I11: =H11*13 -> 1885494 | M11: =SUM(N11:Y11) -> 1885494 | N11: =H11*2 -> 290076 | O11: =H11 -> 145038 | P11: =+O11 -> 145038 | Q11: =+P11 -> 145038 | R11: =+Q11 -> 145038 | S11: =+R11 -> 145038 | T11: =+S11 -> 145038 | U11: =+T11 -> 145038 | V11: =+U11 -> 145038 | W11: =+V11 -> 145038 | ... Y11: =+X11 -> 145038
A12: OPERACION DE VIAS | B12: OPERACION PEAJES | C12: OPERACION INTEGRAL ESTACIÓN DE PEAJE MACHETA | D12: SERVICIO INTEROPERABILIDAD IP/REV | E12: MENSUAL | F12: 12 | G12: 15601887 | H12: =G12*(1+C$3) -> 16397583 | I12: =H12*13 -> 2.1316858e+08 | M12: =SUM(N12:Y12) -> 2.1316858e+08 | N12: =H12*2 -> 32795167 | O12: =H12 -> 16397583 | P12: =O12 -> 16397583 | Q12: =P12 -> 16397583 | R12: =Q12 -> 16397583 | S12: =R12 -> 16397583 | T12: =S12 -> 16397583 | U12: =T12 -> 16397583 | V12: =U12 -> 16397583 | W12: =V12 -> 16397583 | ... Y12: =X12 -> 16397583
A13: OPERACION DE VIAS | B13: OPERACION PEAJES | C13: OPERACION INTEGRAL ESTACIÓN DE PEAJE MACHETA | D13: SERVICIO MTTO SOFTWARE RECAUDO | E13: MENSUAL | F13: 12 | G13: 4171283 | H13: =G13*(1+C$4) -> 5130678.1 | I13: =H13*F13 -> 61568137 | M13: =SUM(N13:Y13) -> 61568137 | N13: =H13 -> 5130678.1 | O13: =+N13 -> 5130678.1 | P13: =+O13 -> 5130678.1 | Q13: =+P13 -> 5130678.1 | R13: =+Q13 -> 5130678.1 | S13: =+R13 -> 5130678.1 | T13: =+S13 -> 5130678.1 | U13: =+T13 -> 5130678.1 | V13: =+U13 -> 5130678.1 | ... Y13: =+X13 -> 5130678.1
A14: OPERACION DE VIAS | B14: OPERACION PEAJES | C14: OPERACION INTEGRAL ESTACIÓN DE PEAJE MACHETA | D14: SERVICIO EMISIÓN DEE | E14: MENSUAL | F14: 12 | G14: =23*87550 -> 2013650 | H14: =G14*(1+C$3) -> 2116346.1 | I14: =H14*13 -> 27512500 | M14: =SUM(N14:Y14) -> 27512500 | N14: =H14*2 -> 4232692.3 | O14: =H14 -> 2116346.1 | P14: =+O14 -> 2116346.1 | Q14: =+P14 -> 2116346.1 | R14: =+Q14 -> 2116346.1 | S14: =+R14 -> 2116346.1 | T14: =+S14 -> 2116346.1 | U14: =+T14 -> 2116346.1 | V14: =+U14 -> 2116346.1 | W14: =+V14 -> 2116346.1 | ... Y14: =+X14 -> 2116346.1
A15: OPERACION DE VIAS | B15: OPERACION PEAJES | C15: OPERACION INTEGRAL ESTACIÓN DE PEAJE MACHETA | D15: STICKER VALLAS TARIFARIAS | E15: UNIDAD | F15: 2 | G15: 285600 | H15: =G15*(1+C$3) -> 300165.6 | I15: =H15*F15 -> 600331.2 | M15: =SUM(N15:Y15) -> 600331.2 | N15: =H15*2 -> 600331.2 | O15: 0 | P15: 0 | Q15: 0 | R15: 0 | S15: 0 | T15: 0 | U15: 0 | V15: 0 | W15: 0 | X15: 0 | Y15: 0
A16: OPERACION DE VIAS | B16: OPERACION PEAJES | C16: OPERACION INTEGRAL ESTACIÓN DE PEAJE MACHETA | D16: BOLETERIA CONTINGENCIA | E16: UNIDAD | F16: 15000 | G16: =171 -> 171 | H16: =G16*(1+C$3) -> 179.721 | I16: =+H16*F16 -> 2695815 | M16: =SUM(N16:Y16) -> 2695815 | N16: 0 | O16: 0 | P16: 0 | Q16: 0 | R16: 0 | S16: 0 | T16: =+H16*F16 -> 2695815 | U16: 0 | V16: 0 | W16: 0 | X16: 0 | Y16: 0
A17: OPERACION DE VIAS | B17: OPERACION PEAJES | C17: OPERACION INTEGRAL ESTACIÓN DE PEAJE MACHETA | D17: CINTA CONSPICUITI | E17: ROLLO | F17: 4 | G17: 406980 | H17: =G17*(1+C$3) -> 427735.98 | I17: =+H17*F17 -> 1710943.9 | M17: =SUM(N17:Y17) -> 1710943.9 | N17: 0 | O17: 0 | P17: 0 | Q17: 0 | R17: =H17*F17 -> 1710943.9 | S17: 0 | T17: 0 | U17: 0 | V17: 0 | W17: 0 | X17: 0 | Y17: 0
A18: OPERACION DE VIAS | B18: OPERACION PEAJES | C18: OPERACION INTEGRAL ESTACIÓN DE PEAJE MACHETA | D18: CONOS 90 CM | E18: UNIDAD | F18: 30 | G18: 88000 | H18: =G18*(1+C$3) -> 92488 | I18: =+H18*F18 -> 2774640 | M18: =SUM(N18:Y18) -> 2774640 | N18: 0 | O18: 0 | P18: 0 | Q18: 0 | R18: 0 | S18: 0 | T18: 0 | U18: 0 | V18: =H18*F18 -> 2774640 | W18: 0 | X18: 0 | Y18: 0
A19: OPERACION DE VIAS | B19: OPERACION PEAJES | C19: OPERACION INTEGRAL ESTACIÓN DE PEAJE MACHETA | D19: PALETAS PARE - SIGA | E19: UNIDAD | F19: 2 | G19: 41067 | H19: =G19*(1+C$3) -> 43161.417 | I19: =+H19*F19 -> 86322.834 | M19: =SUM(N19:Y19) -> 86322.834 | N19: 0 | O19: =H19*F19 -> 86322.834 | P19: 0 | Q19: 0 | R19: 0 | S19: 0 | T19: 0 | U19: 0 | V19: 0 | W19: 0 | X19: 0 | Y19: 0
A20: OPERACION DE VIAS | B20: OPERACION PEAJES | C20: OPERACION INTEGRAL ESTACIÓN DE PEAJE MACHETA | D20: FLASHER SOLAR | E20: UNIDAD | F20: 30 | G20: 41067 | H20: =G20*(1+C$3) -> 43161.417 | I20: =+H20*F20 -> 1294842.5 | M20: =SUM(N20:Y20) -> 1294842.5 | N20: 0 | O20: 0 | P20: 0 | Q20: 0 | R20: 0 | S20: 0 | T20: 0 | U20: =H20*F20 -> 1294842.5 | V20: 0 | W20: 0 | X20: 0 | Y20: 0
A21: OPERACION DE VIAS | B21: OPERACION PEAJES | C21: OPERACION INTEGRAL ESTACIÓN DE PEAJE MACHETA | D21: TALANQUERAS | E21: UNIDAD | F21: 3 | G21: 235620 | H21: =G21*(1+C$3) -> 247636.62 | I21: =+H21*F21 -> 742909.86 | M21: =SUM(N21:Y21) -> 742909.86 | N21: 0 | O21: =H21*F21/2 -> 371454.93 | P21: 0 | Q21: 0 | R21: 0 | S21: 0 | T21: 0 | U21: =O21 -> 371454.93 | V21: 0 | W21: 0 | X21: 0 | Y21: 0
A22: OPERACION DE VIAS | B22: OPERACION PEAJES | C22: OPERACION INTEGRAL ESTACIÓN DE PEAJE SAN LUIS DE GACENO | M22: =SUM(N22:Y22) -> 2.1005054e+09 | N22: =SUM(N23:N35) -> 1.9099262e+08 | O22: =SUM(O23:O35) -> 1.7338887e+08 | P22: =SUM(P23:P35) -> 1.729311e+08 | Q22: =SUM(Q23:Q35) -> 1.729311e+08 | R22: =SUM(R23:R35) -> 1.7464204e+08 | S22: =SUM(S23:S35) -> 1.729311e+08 | T22: =SUM(T23:T35) -> 1.7562691e+08 | U22: =SUM(U23:U35) -> 1.7394997e+08 | ... Y22: =SUM(Y23:Y35) -> 1.729311e+08
A23: OPERACION DE VIAS | B23: OPERACION PEAJES | C23: OPERACION INTEGRAL ESTACIÓN DE PEAJE SAN LUIS DE GACENO | D23: SERVICIO OPERACIÓN PEAJE | E23: MENSUAL | F23: 12 | G23: 126398293 | H23: =G23*(1+C$4) -> 1.554699e+08 | I23: =H23*F23 -> 1.8656388e+09 | M23: =SUM(N23:Y23) -> 1.8656388e+09 | N23: =H23 -> 1.554699e+08 | O23: =+N23 -> 1.554699e+08 | P23: =+O23 -> 1.554699e+08 | Q23: =+P23 -> 1.554699e+08 | R23: =+Q23 -> 1.554699e+08 | S23: =+R23 -> 1.554699e+08 | T23: =+S23 -> 1.554699e+08 | U23: =+T23 -> 1.554699e+08 | V23: =+U23 -> 1.554699e+08 | ... Y23: =+X23 -> 1.554699e+08
A24: OPERACION DE VIAS | B24: OPERACION PEAJES | C24: OPERACION INTEGRAL ESTACIÓN DE PEAJE SAN LUIS DE GACENO | D24: SERVICIO RECAUDADORES APOYO | E24: MENSUAL | F24: 0 | G24: =14076524/3 -> 4692174.7 | H24: =G24*(1+C$4) -> 5771374.8 | I24: =H24*F24 -> 0 | M24: =SUM(N24:Y24) -> 0 | N24: 0 | O24: 0 | P24: 0 | Q24: 0 | R24: 0 | S24: 0 | T24: 0 | U24: 0 | V24: 0 | W24: 0 | X24: =W24 -> 0 | Y24: =X24 -> 0
A25: OPERACION DE VIAS | B25: OPERACION PEAJES | C25: OPERACION INTEGRAL ESTACIÓN DE PEAJE SAN LUIS DE GACENO | D25: SERIVICIO ALQUILER DATAFONOS | E25: MENSUAL | F25: 12 | G25: =69000*2 -> 138000 | H25: =G25*(1+C$3) -> 145038 | I25: =H25*13 -> 1885494 | M25: =SUM(N25:Y25) -> 1885494 | N25: =H25*2 -> 290076 | O25: =H25 -> 145038 | P25: =+O25 -> 145038 | Q25: =+P25 -> 145038 | R25: =+Q25 -> 145038 | S25: =+R25 -> 145038 | T25: =+S25 -> 145038 | U25: =+T25 -> 145038 | V25: =+U25 -> 145038 | W25: =+V25 -> 145038 | ... Y25: =+X25 -> 145038
A26: OPERACION DE VIAS | B26: OPERACION PEAJES | C26: OPERACION INTEGRAL ESTACIÓN DE PEAJE SAN LUIS DE GACENO | D26: SERVICIO INTEROPERABILIDAD IP/REV | E26: MENSUAL | F26: 12 | G26: 15601887 | H26: =G26*(1+C$3) -> 16397583 | I26: =H26*13 -> 2.1316858e+08 | M26: =SUM(N26:Y26) -> 2.1316858e+08 | N26: =H26*2 -> 32795167 | O26: =H26 -> 16397583 | P26: =O26 -> 16397583 | Q26: =P26 -> 16397583 | R26: =Q26 -> 16397583 | S26: =R26 -> 16397583 | T26: =S26 -> 16397583 | U26: =T26 -> 16397583 | V26: =U26 -> 16397583 | W26: =V26 -> 16397583 | ... Y26: =X26 -> 16397583
A27: OPERACION DE VIAS | B27: OPERACION PEAJES | C27: OPERACION INTEGRAL ESTACIÓN DE PEAJE SAN LUIS DE GACENO | D27: SERVICIO MTTO SOFTWARE RECAUDO | E27: MENSUAL | F27: 0 | G27: 4171283 | H27: =G27*(1+C$4) -> 5130678.1 | I27: =H27*F27 -> 0 | M27: =SUM(N27:Y27) -> 0 | N27: 0 | O27: =+N27 -> 0 | P27: =+O27 -> 0 | Q27: =+P27 -> 0 | R27: =+Q27 -> 0 | S27: =+R27 -> 0 | T27: =+S27 -> 0 | U27: =+T27 -> 0 | V27: =+U27 -> 0 | ... Y27: =+X27 -> 0
A28: OPERACION DE VIAS | B28: OPERACION PEAJES | C28: OPERACION INTEGRAL ESTACIÓN DE PEAJE SAN LUIS DE GACENO | D28: SERVICIO EMISIÓN DEE | E28: MENSUAL | F28: 12 | G28: =23*38000 -> 874000 | H28: =G28*(1+C$3) -> 918574 | I28: =H28*13 -> 11941462 | M28: =SUM(N28:Y28) -> 11941462 | N28: =H28*2 -> 1837148 | O28: =H28 -> 918574 | P28: =+O28 -> 918574 | Q28: =+P28 -> 918574 | R28: =+Q28 -> 918574 | S28: =+R28 -> 918574 | T28: =+S28 -> 918574 | U28: =+T28 -> 918574 | V28: =+U28 -> 918574 | W28: =+V28 -> 918574 | ... Y28: =+X28 -> 918574
A29: OPERACION DE VIAS | B29: OPERACION PEAJES | C29: OPERACION INTEGRAL ESTACIÓN DE PEAJE SAN LUIS DE GACENO | D29: STICKER VALLAS TARIFARIAS | E29: UNIDAD | F29: 2 | G29: 285600 | H29: =G29*(1+C$3) -> 300165.6 | I29: =H29*F29 -> 600331.2 | M29: =SUM(N29:Y29) -> 600331.2 | N29: =H29*2 -> 600331.2 | O29: 0 | P29: 0 | Q29: 0 | R29: 0 | S29: 0 | T29: 0 | U29: 0 | V29: 0 | W29: 0 | X29: 0 | Y29: 0
A30: OPERACION DE VIAS | B30: OPERACION PEAJES | C30: OPERACION INTEGRAL ESTACIÓN DE PEAJE SAN LUIS DE GACENO | D30: BOLETERIA CONTINGENCIA | E30: UNIDAD | F30: 15000 | G30: =171 -> 171 | H30: =G30*(1+C$3) -> 179.721 | I30: =+H30*F30 -> 2695815 | M30: =SUM(N30:Y30) -> 2695815 | N30: 0 | O30: 0 | P30: 0 | Q30: 0 | R30: 0 | S30: 0 | T30: =+H30*F30 -> 2695815 | U30: 0 | V30: 0 | W30: 0 | X30: 0 | Y30: 0
A31: OPERACION DE VIAS | B31: OPERACION PEAJES | C31: OPERACION INTEGRAL ESTACIÓN DE PEAJE SAN LUIS DE GACENO | D31: CINTA CONSPICUITI | E31: ROLLO | F31: 4 | G31: 406980 | H31: =G31*(1+C$3) -> 427735.98 | I31: =+H31*F31 -> 1710943.9 | M31: =SUM(N31:Y31) -> 1710943.9 | N31: 0 | O31: 0 | P31: 0 | Q31: 0 | R31: =H31*F31 -> 1710943.9 | S31: 0 | T31: 0 | U31: 0 | V31: 0 | W31: 0 | X31: 0 | Y31: 0
A32: OPERACION DE VIAS | B32: OPERACION PEAJES | C32: OPERACION INTEGRAL ESTACIÓN DE PEAJE SAN LUIS DE GACENO | D32: CONOS 90 CM | E32: UNIDAD | F32: 15 | G32: 88000 | H32: =G32*(1+C$3) -> 92488 | I32: =+H32*F32 -> 1387320 | M32: =SUM(N32:Y32) -> 1387320 | N32: 0 | O32: 0 | P32: 0 | Q32: 0 | R32: 0 | S32: 0 | T32: 0 | U32: 0 | V32: =H32*F32 -> 1387320 | W32: 0 | X32: 0 | Y32: 0
A33: OPERACION DE VIAS | B33: OPERACION PEAJES | C33: OPERACION INTEGRAL ESTACIÓN DE PEAJE SAN LUIS DE GACENO | D33: PALETAS PARE - SIGA | E33: UNIDAD | F33: 2 | G33: 41067 | H33: =G33*(1+C$3) -> 43161.417 | I33: =+H33*F33 -> 86322.834 | M33: =SUM(N33:Y33) -> 86322.834 | N33: 0 | O33: =H33*F33 -> 86322.834 | P33: 0 | Q33: 0 | R33: 0 | S33: 0 | T33: 0 | U33: 0 | V33: 0 | W33: 0 | X33: 0 | Y33: 0
A34: OPERACION DE VIAS | B34: OPERACION PEAJES | C34: OPERACION INTEGRAL ESTACIÓN DE PEAJE SAN LUIS DE GACENO | D34: FLASHER SOLAR | E34: UNIDAD | F34: 15 | G34: 41067 | H34: =G34*(1+C$3) -> 43161.417 | I34: =+H34*F34 -> 647421.25 | M34: =SUM(N34:Y34) -> 647421.25 | N34: 0 | O34: 0 | P34: 0 | Q34: 0 | R34: 0 | S34: 0 | T34: 0 | U34: =H34*F34 -> 647421.25 | V34: 0 | W34: 0 | X34: 0 | Y34: 0
A35: OPERACION DE VIAS | B35: OPERACION PEAJES | C35: OPERACION INTEGRAL ESTACIÓN DE PEAJE SAN LUIS DE GACENO | D35: TALANQUERAS | E35: UNIDAD | F35: 3 | G35: 235620 | H35: =G35*(1+C$3) -> 247636.62 | I35: =+H35*F35 -> 742909.86 | M35: =SUM(N35:Y35) -> 742909.86 | N35: 0 | O35: =H35*F35/2 -> 371454.93 | P35: 0 | Q35: 0 | R35: 0 | S35: 0 | T35: 0 | U35: =O35 -> 371454.93 | V35: 0 | W35: 0 | X35: 0 | Y35: 0
A36: OPERACION DE VIAS | B36: OPERACION PESAJES | C36: OPERACION ESTACIÓN DE PESAJE MACHETA | M36: =SUM(M37:M46) -> 75327505 | N36: =SUM(N37:N46) -> 0 | O36: =SUM(O37:O46) -> 500939.18 | P36: =SUM(P37:P46) -> 27769036 | Q36: =SUM(Q37:Q46) -> 0 | R36: =SUM(R37:R46) -> 13783802 | S36: =SUM(S37:S46) -> 0 | T36: =SUM(T37:T46) -> 0 | ... Y36: =SUM(Y37:Y46) -> 0
A37: OPERACION DE VIAS | B37: OPERACION PESAJES | C37: OPERACION ESTACIÓN DE PESAJE MACHETA | D37: SERVICIO CALIBRACIÓN METROLOGICA | E37: UNIDAD | F37: 1 | G37: 14000571 | H37: =G37*(1+C$3) -> 14714600 | I37: =H37*F37 -> 14714600 | M37: =SUM(N37:Y37) -> 14714600 | N37: 0 | O37: =+N37 -> 0 | P37: 0 | Q37: 0 | R37: 0 | S37: 0 | T37: 0 | U37: 0 | V37: 0 | W37: =I37 -> 14714600 | X37: 0 | Y37: 0
A38: OPERACION DE VIAS | B38: OPERACION PESAJES | C38: OPERACION ESTACIÓN DE PESAJE MACHETA | D38: SERVICIO VERIFICACIÓN SIC | E38: UNIDAD | F38: 1 | G38: 13433102 | H38: =G38*(1+C$3) -> 14118190 | I38: =H38*F38 -> 14118190 | M38: =SUM(N38:Y38) -> 14118190 | N38: 0 | O38: 0 | P38: 0 | Q38: 0 | R38: 0 | S38: 0 | T38: 0 | U38: 0 | V38: 0 | W38: 0 | X38: =I38 -> 14118190 | Y38: 0
A39: OPERACION DE VIAS | B39: OPERACION PESAJES | C39: OPERACION ESTACIÓN DE PESAJE MACHETA | D39: SERVICIO ACTUALIZACIÓN BASCAM | E39: UNIDAD | F39: 1 | G39: 11894000 | H39: =G39*(1+C$3) -> 12500594 | I39: =H39*F39 -> 12500594 | M39: =SUM(N39:Y39) -> 12500594 | N39: 0 | O39: 0 | P39: 0 | Q39: 0 | R39: =I39 -> 12500594 | S39: 0 | T39: 0 | U39: 0 | V39: 0 | W39: 0 | X39: 0 | Y39: 0
A40: OPERACION DE VIAS | B40: OPERACION PESAJES | C40: OPERACION ESTACIÓN DE PESAJE MACHETA | D40: SERVICIO MTTO PREVENTIVO ESTATICA | E40: UNIDAD | F40: 1 | G40: 2921538 | H40: =G40*(1+C$3) -> 3070536.4 | I40: =H40*F40 -> 3070536.4 | M40: =SUM(N40:Y40) -> 3070536.4 | N40: 0 | O40: 0 | P40: =H40 -> 3070536.4 | Q40: 0 | R40: 0 | S40: 0 | T40: 0 | U40: 0 | V40: 0 | W40: 0 | X40: 0 | Y40: 0
A41: OPERACION DE VIAS | B41: OPERACION PESAJES | C41: OPERACION ESTACIÓN DE PESAJE MACHETA | D41: SERVICIO MTTO PREVENTIVO DINAMICAS | E41: UNIDAD | F41: 1 | G41: 23500000 | H41: =G41*(1+C$3) -> 24698500 | I41: =H41*F41 -> 24698500 | M41: =SUM(N41:Y41) -> 24698500 | N41: 0 | O41: =+N41 -> 0 | P41: =H41 -> 24698500 | Q41: 0 | R41: 0 | S41: 0 | T41: 0 | U41: 0 | V41: 0 | W41: 0 | X41: 0 | Y41: 0
A42: OPERACION DE VIAS | B42: OPERACION PESAJES | C42: OPERACION ESTACIÓN DE PESAJE MACHETA | D42: CINTA CONSPICUITI | E42: ROLLO | F42: 3 | G42: 406980 | H42: =G42*(1+C$3) -> 427735.98 | I42: =+H42*F42 -> 1283207.9 | M42: =SUM(N42:Y42) -> 1283207.9 | N42: 0 | O42: 0 | P42: 0 | Q42: 0 | R42: =H42*F42 -> 1283207.9 | S42: 0 | T42: 0 | U42: 0 | V42: 0 | W42: 0 | X42: 0 | Y42: 0
...

Sheet Polca
B2: Variable
B3: IPC (dic/dic) | C3: 4,0%
B4: Salario mínimo | C4: 0.08
B5: TRM promedio (COP/USD) | C5: $4.250
A7: Capítulo | B7: ítem | C7: Insumo | D7: Descripción | E7: Unidad | F7: Cantidad 2026 | G7: Precio Base 2025 | H7: Precio Base 2026 | I7: Valor Total | J7: Supuestos | K7: Observaciones | L7: Soporte | M7: Total Presupuesto 2026 | N7: Enero | O7: febrero | P7: marzo | Q7: abril | R7: mayo | S7: junio | T7: julio | U7: agosto | V7: septiembre | W7: octubre | X7: noviembre | Y7: diciembre
A8: POLICIA DE CARRETERAS | B8: VIATICOS POLCA | C8: VIATICOS POLCA - AÑO 2026 - NUEVO CONVENIO | M8: =SUM(N8:Y8) -> 1.429377e+09 | N8: 115086719 | O8: 115086719 | P8: 115086719 | Q8: 115086719 | R8: 115086719 | S8: 115086719 | T8: 1.2314279e+08 | U8: 1.2314279e+08 | V8: 1.2314279e+08 | W8: 1.2314279e+08 | X8: 1.2314279e+08 | Y8: 1.2314279e+08
A9: POLICIA DE CARRETERAS | B9: MANTENIMIENTO EQUIPOS POLCA | C9: MANTENIMIENTO EQUIPOS POLCA AÑO 2026 - NUEVO CONVENIO | M9: =SUM(N9:Y9) -> 1.1807488e+09 | N9: 88491254 | O9: 1.4410319e+08 | P9: 74884833 | Q9: 60553175 | R9: 2.6469757e+08 | S9: 1.0312527e+08 | T9: 82837938 | U9: 57543095 | V9: 78261761 | W9: 81195372 | X9: 79919156 | Y9: 65136169
M10: =SUM(M8:M9) -> 2.6101258e+09
A12: OTRAS INVERSIONES - RESERVA - AFECTAN PRESUPUESTO 2025
A13: POLICIA DE CARRETERAS | B13: VIATICOS POLCA | C13: VIATICOS POLCA NO INVERTIDOS DIC-2022 A DIC-2025 (Reserva) | M13: =SUM(N13:Y13) -> 3271006358 | N13: 3271006358
M14: =SUM(M13:M13) -> 3271006358

Sheet Inversion Activos
B2: Variable
B3: IPC (dic/dic) | C3: 4,0%
B4: Salario mínimo | C4: 0.08
B5: TRM promedio (COP/USD) | C5: $4.250
A7: Capítulo | B7: ítem | C7: Insumo | D7: Descripción | E7: Unidad | F7: Cantidad 2026 | G7: Precio Base 2025 | H7: Precio Base 2026 | I7: Valor Total | J7: Supuestos | K7: Observaciones | L7: Soporte | M7: Total Presupuesto 2026 | N7: Enero | O7: febrero | P7: marzo | Q7: abril | R7: mayo | S7: junio | T7: julio | U7: agosto | V7: septiembre | W7: octubre | X7: noviembre | Y7: diciembre
A8: INVERSIÓN ACTIVOS | B8: CONVENIO POLCA | C8: EQUIPOS Y ELEMENTOS NUEVO CONVENIO 2026 | K8: indicar si existe algun valor por retoma y el año del equipo que se reemplaza | M8: 6.1832794e+09 | N8: 6.1832794e+09 | O8: 0 | P8: 0 | Q8: 0 | R8: 0 | S8: 0 | T8: 0 | U8: 0 | V8: 0 | W8: 0 | X8: 0 | Y8: 0
A9: INVERSIÓN ACTIVOS | B9: SISTEMAS ILUMINACIÓN | C9: CAMBIO LUMINARIAS TUNELES UF 2 (LAS JUNTAS Y EL INFIERNO) | K9: Indicar para que área será asignado, si el anterior se da de baja o se reasigna y el año del equipo | M9: =SUM(N9:Y9) -> 1300000000 | N9: 1300000000 | O9: 0 | P9: 0 | Q9: 0 | R9: 0 | S9: 0 | T9: 0 | U9: 0 | V9: 0 | W9: 0 | X9: 0 | Y9: 0
A10: INVERSIÓN ACTIVOS | B10: SISTEMAS DE ENERGÍA | C10: PROYECTOS DE EFICIENCIA ENERGETICA EDIFICACIONES (Optativo supeditado a conveniencia de amortización de inversión) | K10: Indicar para que área será asignado, si el anterior se da de baja o se reasigna y el año del equipo | M10: =SUM(N10:Y10) -> 1015000000 | N10: 1015000000 | O10: 0 | P10: 0 | Q10: 0 | R10: 0 | S10: 0 | T10: 0 | U10: 0 | V10: 0 | W10: 0 | X10: 0 | Y10: 0
M11: =SUM(M8:M10) -> 8.4982794e+09
A12: OTRAS INVERSIONES - RESERVA - AFECTAN PRESUPUESTO 2025
A13: INVERSIÓN ACTIVOS | B13: CONVENIO POLCA | C13: EQUIPOS Y ELEMENTOS - ACTA DE LIQUIDACIÓN CONVENIO 2016 A 2022 (Reserva) (Afecta Preupuesto 2025) | K13: indicar si existe algun valor por retoma y el año del equipo que se reemplaza | M13: 973966517 | N13: 973966517
A14: INVERSIÓN ACTIVOS | B14: CONVENIO POLCA | C14: ELEMENTOS POLCA NO INVERTIDOS DIC-2022 A DIC-2025 (Reserva) (Afecta Preupuesto 2025) | K14: indicar si existe algun valor por retoma y el año del equipo que se reemplaza | M14: 3.2250365e+09 | N14: 3.2250365e+09
K15: indicar si existe algun valor por retoma y el año del equipo que se reemplaza | M15: =SUM(M13:M14) -> 4.199003e+09

Sheet Gestión Ambiental
B2: Variable
B3: IPC (dic/dic) | C3: 4,0%
B4: Salario mínimo | C4: 0.08
B5: TRM promedio (COP/USD) | C5: $4.250
A7: Capítulo | B7: ítem | C7: Insumo | D7: Descripción | E7: Unidad | F7: Cantidad 2026 | G7: Precio Base 2025 | H7: Precio Base 2026 | I7: Valor Total | J7: Supuestos | K7: Observaciones | L7: Soporte | M7: Total Presupuesto 2026 | N7: Enero | O7: febrero | P7: marzo | Q7: abril | R7: mayo | S7: junio | T7: julio | U7: agosto | V7: septiembre | W7: octubre | X7: noviembre | Y7: diciembre
A8: GESTION AMBIENTAL

Sheet Gestión Social
B2: Variable
B3: IPC (dic/dic) | C3: 4,0%
B4: Salario mínimo | C4: 0.08
B5: TRM promedio (COP/USD) | C5: $4.250
A7: Capítulo | B7: ítem | C7: Insumo | D7: Descripción | E7: Unidad | F7: Cantidad 2026 | G7: Precio Base 2025 | H7: Precio Base 2026 | I7: Valor Total | J7: Supuestos | K7: Observaciones | L7: Soporte | M7: Total Presupuesto 2026 | N7: Enero | O7: febrero | P7: marzo | Q7: abril | R7: mayo | S7: junio | T7: julio | U7: agosto | V7: septiembre | W7: octubre | X7: noviembre | Y7: diciembre
A8: GESTION SOCIAL

Sheet Gestión Predial
B2: Variable
B3: IPC (dic/dic) | C3: 4,0%
B4: Salario mínimo | C4: 0.08
B5: TRM promedio (COP/USD) | C5: $4.250
A7: Capítulo | B7: ítem | C7: Insumo | D7: Descripción | E7: Unidad | F7: Cantidad 2026 | G7: Precio Base 2025 | H7: Precio Base 2026 | I7: Valor Total | J7: Supuestos | K7: Observaciones | L7: Soporte | M7: Total Presupuesto 2026 | N7: Enero | O7: febrero | P7: marzo | Q7: abril | R7: mayo | S7: junio | T7: julio | U7: agosto | V7: septiembre | W7: octubre | X7: noviembre | Y7: diciembre
A8: GESTION PREDIAL

Sheet Jurídica
B2: Variable
B3: IPC (dic/dic) | C3: 4,0%
B4: Salario mínimo | C4: 0.08
B5: TRM promedio (COP/USD) | C5: $4.250
A7: Capítulo | B7: ítem | C7: Insumo | D7: Descripción | E7: Unidad | F7: Cantidad 2026 | G7: Precio Base 2025 | H7: Precio Base 2026 | I7: Valor Total | J7: Supuestos | K7: Observaciones | L7: Soporte | M7: Total Presupuesto 2026 | N7: Enero | O7: febrero | P7: marzo | Q7: abril | R7: mayo | S7: junio | T7: julio | U7: agosto | V7: septiembre | W7: octubre | X7: noviembre | Y7: diciembre
A8: JURIDICA

Sheet SST
B2: Variable
B3: IPC (dic/dic) | C3: 4,0%
B4: Salario mínimo | C4: 0.08
B5: TRM promedio (COP/USD) | C5: $4.250
A7: Capítulo | B7: ítem | C7: Insumo | D7: Descripción | E7: Unidad | F7: Cantidad 2026 | G7: Precio Base 2025 | H7: Precio Base 2026 | I7: Valor Total | J7: Supuestos | K7: Observaciones | L7: Soporte | M7: Total Presupuesto 2026 | N7: Enero | O7: febrero | P7: marzo | Q7: abril | R7: mayo | S7: junio | T7: julio | U7: agosto | V7: septiembre | W7: octubre | X7: noviembre | Y7: diciembre
A8: =Capítulos!A4 -> SST | B8: DOTACION | C8: CAMISAS MUJER BLANCA TALLA XS | H8: =G8*(1+$C$3) -> 0 | I8: =+F8*H8 -> 0
A9: SST | B9: DOTACION | C9: CAMISAS MUJER BLANCA TALLA S | H9: =G9*(1+$C$3) -> 0 | I9: =+F9*H9 -> 0
A10: SST | B10: DOTACION | C10: CAMISAS HOMBRE BLANCAS TALLA L | H10: =G10*(1+$C$3) -> 0 | I10: =+F10*H10 -> 0
A11: SST | B11: DOTACION | C11: CAMISAS HOMBRE BLANCAS TALLA XL | H11: =G11*(1+$C$3) -> 0 | I11: =+F11*H11 -> 0
A12: SST | B12: DOTACION | C12: CAMISAS HOMBRE AZUL TALLA L 0 CONSERJE | H12: =G12*(1+$C$3) -> 0 | I12: =+F12*H12 -> 0
A13: SST | B13: DOTACION | C13: CAMISAS HOMBRE AZUL TALLA XL 0 CONSERJE | H13: =G13*(1+$C$3) -> 0 | I13: =+F13*H13 -> 0
A14: SST | B14: DOTACION | C14: PANTALÓN JEANS MUJER TALLA 10 | H14: =G14*(1+$C$3) -> 0 | I14: =+F14*H14 -> 0
A15: SST | B15: DOTACION | C15: PANTALÓN JEANS MUJER TALLA 12 | H15: =G15*(1+$C$3) -> 0 | I15: =+F15*H15 -> 0
A16: SST | B16: DOTACION | C16: PANTALÓN JEANS HOMBRE TALLA 40 | H16: =G16*(1+$C$3) -> 0 | I16: =+F16*H16 -> 0
A17: SST | B17: DOTACION | C17: PANTALÓN JEANS HOMBRE TALLA 42 | H17: =G17*(1+$C$3) -> 0 | I17: =+F17*H17 -> 0
A18: SST | B18: DOTACION | C18: CHAQUETA TALLA XL DAMA | H18: =G18*(1+$C$3) -> 0 | I18: =+F18*H18 -> 0
A19: SST | B19: DOTACION | C19: CHAQUETA TALLA XXL HOMBRE | H19: =G19*(1+$C$3) -> 0 | I19: =+F19*H19 -> 0
A20: SST | B20: DOTACION | C20: CONJUNTO ANTIFLUIDO TALLA S | H20: =G20*(1+$C$3) -> 0 | I20: =+F20*H20 -> 0
... A28: SST | B28: EPPS | C28: GASCOS | H28: =G28*(1+$C$3) -> 0 | I28: =+F28*H28 -> 0

Sheet Pólizas
B2: Variable
B3: IPC (dic/dic) | C3: 4,0%
B4: Salario mínimo | C4: 0.08
B5: TRM promedio (COP/USD) | C5: $4.250
A7: Capítulo | B7: ítem | C7: Insumo | D7: Descripción | E7: Unidad | F7: Cantidad 2026 | G7: Precio Base 2025 | H7: Precio Base 2026 | I7: Valor Total | J7: Supuestos | K7: Observaciones | L7: Soporte | M7: Total Presupuesto 2026 | N7: Enero | O7: febrero | P7: marzo | Q7: abril | R7: mayo | S7: junio | T7: julio | U7: agosto | V7: septiembre | W7: octubre | X7: noviembre | Y7: diciembre
A8: POLIZAS | B8: CUMPLIMIENTO
A9: POLIZAS | B9: SALARIOS Y PRESTACIONES SOCIALES
A10: POLIZAS | B10: ESTABILIDAD Y CALIDAD
A11: POLIZAS | B11: D&O
A12: POLIZAS | B12: AUTOS
A13: POLIZAS | B13: RC AMBIENTAL
A14: POLIZAS | B14: RESPONSABILIDAD CIVIL EXTRACONTRACTUAL
A15: POLIZAS | B15: OBRA CIVIL TERMINADA
A16: POLIZAS | B16: TODO RIESGO CONSTRUCCION

Sheet Administración
B2: Variable
B3: IPC (dic/dic) | C3: 4,0%
B4: Salario mínimo | C4: 0.08
B5: TRM promedio (COP/USD) | C5: $4.250
A7: Capítulo | B7: ítem | C7: Insumo | D7: Descripción | E7: Unidad | F7: Cantidad 2026 | G7: Precio Base 2025 | H7: Precio Base 2026 | I7: Valor Total | J7: Supuestos | K7: Observaciones | L7: Soporte | M7: Total Presupuesto 2026 | N7: Enero | O7: febrero | P7: marzo | Q7: abril | R7: mayo | S7: junio | T7: julio | U7: agosto | V7: septiembre | W7: octubre | X7: noviembre | Y7: diciembre
A8: =Capítulos!$A$2 -> ADMINISTRACION | B8: GASTOS GENERALES OFICINA BOGOTÁ | C8: ARRENDAMIENTO OFICINA | D8: Arrendamiento oficina Teleport 502 | E8: Mes | F8: 12 | G8: 11305000 | H8: =G8*(1+$C$3) -> 11757200 | I8: =+F8*H8 -> 141086400 | J8: Consumo estimado para el año 2026 | K8: precio según contrato | L8: Contrato de Arrendamiento suscrito en 2025 | M8: =SUM(N8:Y8) -> 141086400 | N8: =+I8/$F8 -> 11757200 | O8: =+$I$8/$F$8 -> 11757200 | P8: =+$I$8/$F$8 -> 11757200 | Q8: =+$I$8/$F$8 -> 11757200 | R8: =+$I$8/$F$8 -> 11757200 | S8: =+$I$8/$F$8 -> 11757200 | T8: =+$I$8/$F$8 -> 11757200 | U8: =+$I$8/$F$8 -> 11757200 | V8: =+$I$8/$F$8 -> 11757200 | ... Y8: =+$I$8/$F$8 -> 11757200
A9: =Capítulos!$A$2 -> ADMINISTRACION | B9: GASTOS GENERALES OFICINA BOGOTÁ | C9: ADMINISTRACIÓN OFICINA | D9: Administración oficina Teleport 502 | E9: Mes | F9: 12 | G9: 2258812 | H9: =G9*(1+$C$3) -> 2349164.5 | I9: =+F9*H9 -> 28189974 | J9: Consumo estimado para el año 2026 | K9: precio según contrato | L9: Contrato de Administración suscrito en 2025 | M9: =SUM(N9:Y9) -> 28189974 | N9: =+$I$9/$F$9 -> 2349164.5 | O9: =+$I$9/$F$9 -> 2349164.5 | P9: =+$I$9/$F$9 -> 2349164.5 | Q9: =+$I$9/$F$9 -> 2349164.5 | R9: =+$I$9/$F$9 -> 2349164.5 | S9: =+$I$9/$F$9 -> 2349164.5 | T9: =+$I$9/$F$9 -> 2349164.5 | U9: =+$I$9/$F$9 -> 2349164.5 | ... Y9: =+$I$9/$F$9 -> 2349164.5
A10: =Capítulos!$A$2 -> ADMINISTRACION | B10: GASTOS PAPELERIA OFICINA BOGOTÁ | C10: ALMOHADILLA DACTILAR | D10: Almohadilla X 4000 Huellas | E10: unidad | F10: 10 | G10: 5000 | H10: =G10*(1+$C$3) -> 5200 | I10: =+F10*H10 -> 52000 | J10: Consumo estimado para el año 2026 | K10: Precio promedio de mercado | L10: Cotización | M10: =SUM(N10:Y10) -> 52000 | O10: =+$I$10/3 -> 17333.333 | S10: =+$I$10/3 -> 17333.333 | W10: =+$I$10/3 -> 17333.333
A11: =Capítulos!$A$2 -> ADMINISTRACION | B11: GASTOS PAPELERIA OFICINA BOGOTÁ | C11: AZ CARTA AZUL PLASTIFICADO | D11: AZ para archivo | E11: unidad | F11: 500 | G11: 700 | H11: =G11*(1+$C$3) -> 728 | I11: =+F11*H11 -> 364000 | J11: Consumo estimado para el año 2026 | K11: Precio promedio de mercado | L11: Cotización | M11: =SUM(N11:Y11) -> 364000 | O11: =+$I$11/3 -> 121333.33 | S11: =+$I$11/3 -> 121333.33 | W11: =+$I$11/3 -> 121333.33
A12: =Capítulos!$A$2 -> ADMINISTRACION | B12: GASTOS PAPELERIA OFICINA BOGOTÁ | C12: AZ OFICIO AZUL PLASTIFICADO | D12: AZ para archivo | E12: unidad | F12: 1000 | G12: 800 | H12: =G12*(1+$C$3) -> 832 | I12: =+F12*H12 -> 832000 | J12: Consumo estimado para el año 2026 | K12: Precio promedio de mercado | L12: Cotización | M12: =SUM(N12:Y12) -> 832000 | O12: =+$I$12/3 -> 277333.33 | S12: =+$I$12/3 -> 277333.33 | W12: =+$I$12/3 -> 277333.33
A13: =Capítulos!$A$2 -> ADMINISTRACION | B13: GASTOS PAPELERIA OFICINA BOGOTÁ | C13: BANDERITAS COLORES | D13: Banderitas por 5 unidades paquete | E13: unidad | F13: 10 | G13: 4000 | H13: =G13*(1+$C$3) -> 4160 | I13: =+F13*H13 -> 41600 | J13: Consumo estimado para el año 2026 para las 5 sedes | K13: Precio promedio de mercado | L13: Cotización | M13: =SUM(N13:Y13) -> 41600 | O13: =+$I$13/3 -> 13866.667 | S13: =+$I$13/3 -> 13866.667 | W13: =+$I$13/3 -> 13866.667
A14: =Capítulos!$A$2 -> ADMINISTRACION | B14: GASTOS PAPELERIA OFICINA BOGOTÁ | C14: BISTURI GRANDE PLASTICO | H14: =G14*(1+$C$3) -> 0 | I14: =+F14*H14 -> 0 | M14: =SUM(N14:Y14) -> 0
A15: =Capítulos!$A$2 -> ADMINISTRACION | B15: GASTOS PAPELERIA OFICINA BOGOTÁ | C15: BLOCK AMARILLO MEDIA CARTA CUADRICULADO 50H | H15: =G15*(1+$C$3) -> 0 | I15: =+F15*H15 -> 0 | M15: =SUM(N15:Y15) -> 0
A16: =Capítulos!$A$2 -> ADMINISTRACION | B16: GASTOS PAPELERIA OFICINA BOGOTÁ | C16: BLOCK IRIS CARTA X 35 HOJAS | H16: =G16*(1+$C$3) -> 0 | I16: =+F16*H16 -> 0 | M16: =SUM(N16:Y16) -> 0
A17: =Capítulos!$A$2 -> ADMINISTRACION | B17: GASTOS PAPELERIA OFICINA BOGOTÁ | C17: BLOCK MILIMETRADO OFICIO 25H | H17: =G17*(1+$C$3) -> 0 | I17: =+F17*H17 -> 0 | M17: =SUM(N17:Y17) -> 0
A18: =Capítulos!$A$2 -> ADMINISTRACION | B18: GASTOS PAPELERIA OFICINA BOGOTÁ | C18: BOLSA DE VINILO CARTA DELGADA PAQUETE X 20 UND | H18: =G18*(1+$C$3) -> 0 | I18: =+F18*H18 -> 0 | M18: =SUM(N18:Y18) -> 0
A19: =Capítulos!$A$2 -> ADMINISTRACION | B19: GASTOS GENERALES OFICINA CCO | H19: =G19*(1+$C$3) -> 0 | I19: =+F19*H19 -> 0
A20: =Capítulos!$A$2 -> ADMINISTRACION | B20: GASTOS GENERALES AREA SERVICIOS SLG | H20: =G20*(1+$C$3) -> 0 | I20: =+F20*H20 -> 0
A21: =Capítulos!$A$2 -> ADMINISTRACION | B21: GASTOS GENERALES AREA SERVICIOS MACHETA | H21: =G21*(1+$C$3) -> 0 | I21: =+F21*H21 -> 0
A22: =Capítulos!$A$2 -> ADMINISTRACION | B22: GASTOS GENERALES PEAJE SLG | H22: =G22*(1+$C$3) -> 0 | I22: =+F22*H22 -> 0
A23: =Capítulos!$A$2 -> ADMINISTRACION | B23: GASTOS GENERALES PEAJE MACHETA | H23: =G23*(1+$C$3) -> 0 | I23: =+F23*H23 -> 0
A24: =Capítulos!$A$2 -> ADMINISTRACION | B24: BAÑOS MOVILES | H24: =G24*(1+$C$3) -> 0 | I24: =+F24*H24 -> 0
A25: =Capítulos!$A$2 -> ADMINISTRACION | B25: ASESORIAS Y AFILIACIONES | H25: =G25*(1+$C$3) -> 0 | I25: =+F25*H25 -> 0

Sheet Financiera
B2: Variable
B3: IPC (dic/dic) | C3: 4,0%
B4: Salario mínimo | C4: 0.08
B5: TRM promedio (COP/USD) | C5: $4.250
A7: Capítulo | B7: ítem | C7: Insumo | D7: Descripción | E7: Unidad | F7: Cantidad 2026 | G7: Precio Base 2025 | H7: Precio Base 2026 | I7: Valor Total | J7: Supuestos | K7: Observaciones | L7: Soporte | M7: Total Presupuesto 2026 | N7: Enero | O7: febrero | P7: marzo | Q7: abril | R7: mayo | S7: junio | T7: julio | U7: agosto | V7: septiembre | W7: octubre | X7: noviembre | Y7: diciembre
A8: FINANCIERA | B8: COSTOS FINANCIEROS
A9: FINANCIERA | B9: COMISION FIDUCIARIA
A10: FINANCIERA | B10: HONORARIOS AGENTE ADMINISTRATIVO
A11: FINANCIERA | B11: HONORARIOS AGENTE ADMINISTRATIVO LIQUIDEZ
A12: FINANCIERA | B12: HONORARIOS AGENTE GARANTÍAS
A13: FINANCIERA | B13: CUARTO DE DATOS
A14: FINANCIERA | B14: ASESOR LEGAL PRESTAMISTA
A15: FINANCIERA | B15: ASESOR LEGAL DEUDOR
A16: FINANCIERA | B16: INGENIERO INDEPENDIENTE | C16: ADICIONAL CERTIFICADO CAMBIO CLIMATICO
A17: FINANCIERA | B17: INGENIERO INDEPENDIENTE | C17: MEMO REVISION PRESUPUESTO
A18: FINANCIERA | B18: INGENIERO INDEPENDIENTE | C18: CERTIFICADO DISPENSA WAIVER
A19: FINANCIERA | B19: INGENIERO INDEPENDIENTE | C19: REVISION PLAN DE OBRA HITOS
A20: FINANCIERA | B20: INGENIERO INDEPENDIENTE | C20: INFORME SEMESTRAL TECNICO OPERACION
A21: FINANCIERA | B21: INGENIERO INDEPENDIENTE | C21: INFORME SEMESTRAL SOCIO AMBIENTAL OPERACION
A22: FINANCIERA | B22: PAGO CAPITAL DEUDA
A23: FINANCIERA | B23: PAGO INTERESES DEUDA
A24: FINANCIERA | B24: HONORARIOS REVISOR FISCAL
A25: FINANCIERA | B25: HONORARIOS AUDITOR EXTERNO
A26: FINANCIERA | B26: HONORARIOS CONSULTAS TRIBUTARIAS
A27: FINANCIERA | B27: HONORARIOS CONSULTAS niif
A28: FINANCIERA | B28: AGENTE DE CALCULO TERMINACION
A29: FINANCIERA | B29: ACTUALIZACIÓN MODELO FINANCIERO
A30: FINANCIERA | B30: AUDITORIA MDELO FINANCIERO
A31: FINANCIERA | B31: CAMARA DE COMERCIO

Sheet Fondeos
B2: Variable
B3: IPC (dic/dic) | C3: 4,0%
B4: Salario mínimo | C4: 0.08
B5: TRM promedio (COP/USD) | C5: $4.250
A7: Capítulo | B7: ítem | C7: Insumo | D7: Descripción | E7: Unidad | F7: Cantidad 2026 | G7: Precio Base 2025 | H7: Precio Base 2026 | I7: Valor Total | J7: Supuestos | K7: Observaciones | L7: Soporte | M7: Total Presupuesto 2026 | N7: Enero | O7: febrero | P7: marzo | Q7: abril | R7: mayo | S7: junio | T7: julio | U7: agosto | V7: septiembre | W7: octubre | X7: noviembre | Y7: diciembre
A8: FONDEOS | B8: INTERVENTORIA Y SUPERVISION
A9: FONDEOS | B9: SOPORTE CONSTRACTUAL
A10: FONDEOS | B10: APORTE ANUAL -MASC
A11: FONDEOS | B11: PRIMER APORTE SEMESTRAL -MASC

Sheet Impuestos 
B2: Variable
B3: IPC (dic/dic) | C3: 4,0%
B4: Salario mínimo | C4: 0.08
B5: TRM promedio (COP/USD) | C5: $4.250
A7: Capítulo | B7: ítem | C7: Insumo | D7: Descripción | E7: Unidad | F7: Cantidad 2026 | G7: Precio Base 2025 | H7: Precio Base 2026 | I7: Valor Total | J7: Supuestos | K7: Observaciones | L7: Soporte | M7: Total Presupuesto 2026 | N7: Enero | O7: febrero | P7: marzo | Q7: abril | R7: mayo | S7: junio | T7: julio | U7: agosto | V7: septiembre | W7: octubre | X7: noviembre | Y7: diciembre
A8: IMPUESTOS | B8: APORTE SUPER TRANSPORTE
A9: IMPUESTOS | B9: APORTE FONTUR
A10: IMPUESTOS | B10: APORTE FONSECON
A11: IMPUESTOS | B11: ICA
A12: IMPUESTOS | B12: ICA MUNICIPIOS
A13: IMPUESTOS | B13: AUTORETENCION
